[2025-06-08T14:52:42.998+0000] {taskinstance.py:1956} INFO - Dependencies all met for dep_context=non-requeueable deps ti=<TaskInstance: transform_customers_csv.run_transformation_us scheduled__2025-06-03T00:00:00+00:00 [queued]>
[2025-06-08T14:52:43.027+0000] {taskinstance.py:1956} INFO - Dependencies all met for dep_context=requeueable deps ti=<TaskInstance: transform_customers_csv.run_transformation_us scheduled__2025-06-03T00:00:00+00:00 [queued]>
[2025-06-08T14:52:43.028+0000] {taskinstance.py:2170} INFO - Starting attempt 1 of 1
[2025-06-08T14:52:43.064+0000] {taskinstance.py:2191} INFO - Executing <Task(_PythonDecoratedOperator): run_transformation_us> on 2025-06-03 00:00:00+00:00
[2025-06-08T14:52:43.080+0000] {standard_task_runner.py:60} INFO - Started process 25789 to run task
[2025-06-08T14:52:43.096+0000] {standard_task_runner.py:87} INFO - Running: ['airflow', 'tasks', 'run', 'transform_customers_csv', 'run_transformation_us', 'scheduled__2025-06-03T00:00:00+00:00', '--job-id', '429', '--raw', '--subdir', 'DAGS_FOLDER/staging/customer_to_staging.py', '--cfg-path', '/tmp/tmp20c9wq12']
[2025-06-08T14:52:43.102+0000] {standard_task_runner.py:88} INFO - Job 429: Subtask run_transformation_us
[2025-06-08T14:52:43.319+0000] {logging_mixin.py:188} WARNING - /home/airflow/.local/lib/python3.10/site-packages/airflow/settings.py:194 DeprecationWarning: The sql_alchemy_conn option in [core] has been moved to the sql_alchemy_conn option in [database] - the old setting has been used, but please update your config.
[2025-06-08T14:52:43.453+0000] {task_command.py:423} INFO - Running <TaskInstance: transform_customers_csv.run_transformation_us scheduled__2025-06-03T00:00:00+00:00 [running]> on host f7e9b9614623
[2025-06-08T14:52:43.805+0000] {taskinstance.py:2480} INFO - Exporting env vars: AIRFLOW_CTX_DAG_OWNER='airflow' AIRFLOW_CTX_DAG_ID='transform_customers_csv' AIRFLOW_CTX_TASK_ID='run_transformation_us' AIRFLOW_CTX_EXECUTION_DATE='2025-06-03T00:00:00+00:00' AIRFLOW_CTX_TRY_NUMBER='1' AIRFLOW_CTX_DAG_RUN_ID='scheduled__2025-06-03T00:00:00+00:00'
[2025-06-08T14:52:43.808+0000] {logging_mixin.py:188} INFO - Starting transformation for table: customers in region: us
[2025-06-08T14:53:12.138+0000] {logging_mixin.py:188} INFO - Reading data from: /opt/airflow/data/raw/region=us/table=customers/load_date=2025-06-06/
[2025-06-08T14:53:51.941+0000] {logging_mixin.py:188} INFO - [INFO] Processing 25 records for us
[2025-06-08T14:53:52.335+0000] {local_task_job_runner.py:296} WARNING - DagRun timed out after 1:00:04.230455.
[2025-06-08T14:53:56.935+0000] {logging_mixin.py:188} INFO - Sample transformed data for us:
[2025-06-08T14:53:57.680+0000] {local_task_job_runner.py:296} WARNING - DagRun timed out after 1:00:09.588205.
[2025-06-08T14:53:57.683+0000] {local_task_job_runner.py:302} WARNING - State of this instance has been externally set to skipped. Terminating instance.
[2025-06-08T14:53:57.811+0000] {process_utils.py:131} INFO - Sending 15 to group 25789. PIDs of all processes in the group: [25813, 25838, 25789]
[2025-06-08T14:53:57.847+0000] {process_utils.py:86} INFO - Sending the signal 15 to group 25789
[2025-06-08T14:53:57.859+0000] {taskinstance.py:2450} ERROR - Received SIGTERM. Terminating subprocesses.
[2025-06-08T14:53:57.870+0000] {clientserver.py:538} INFO - Error while receiving.
Traceback (most recent call last):
  File "/home/airflow/.local/lib/python3.10/site-packages/py4j/clientserver.py", line 511, in send_command
    answer = smart_decode(self.stream.readline()[:-1])
  File "/usr/local/lib/python3.10/socket.py", line 705, in readinto
    return self._sock.recv_into(b)
  File "/home/airflow/.local/lib/python3.10/site-packages/airflow/models/taskinstance.py", line 2452, in signal_handler
    raise AirflowException("Task received SIGTERM signal")
airflow.exceptions.AirflowException: Task received SIGTERM signal
[2025-06-08T14:53:57.892+0000] {clientserver.py:543} INFO - Closing down clientserver connection
[2025-06-08T14:53:57.896+0000] {java_gateway.py:1055} ERROR - Exception while sending command.
Traceback (most recent call last):
  File "/home/airflow/.local/lib/python3.10/site-packages/py4j/clientserver.py", line 511, in send_command
    answer = smart_decode(self.stream.readline()[:-1])
  File "/usr/local/lib/python3.10/socket.py", line 705, in readinto
    return self._sock.recv_into(b)
  File "/home/airflow/.local/lib/python3.10/site-packages/airflow/models/taskinstance.py", line 2452, in signal_handler
    raise AirflowException("Task received SIGTERM signal")
airflow.exceptions.AirflowException: Task received SIGTERM signal

During handling of the above exception, another exception occurred:

Traceback (most recent call last):
  File "/home/airflow/.local/lib/python3.10/site-packages/py4j/java_gateway.py", line 1038, in send_command
    response = connection.send_command(command)
  File "/home/airflow/.local/lib/python3.10/site-packages/py4j/clientserver.py", line 539, in send_command
    raise Py4JNetworkError(
py4j.protocol.Py4JNetworkError: Error while sending or receiving
[2025-06-08T14:53:57.903+0000] {clientserver.py:543} INFO - Closing down clientserver connection
[2025-06-08T14:53:57.904+0000] {logging_mixin.py:188} INFO - Error transforming data for us: An error occurred while calling o183.showString
[2025-06-08T14:53:58.981+0000] {process_utils.py:79} INFO - Process psutil.Process(pid=25838, status='terminated', started='14:52:44') (25838) terminated with exit code None
[2025-06-08T14:53:58.963+0000] {clientserver.py:538} INFO - Error while receiving.
Traceback (most recent call last):
  File "/opt/airflow/scripts/pyspark_jobs/customer.py", line 68, in transform_customers_table
    raise e
  File "/opt/airflow/scripts/pyspark_jobs/customer.py", line 54, in transform_customers_table
    df_transformed.show(5, truncate=False)
  File "/home/airflow/.local/lib/python3.10/site-packages/pyspark/sql/dataframe.py", line 945, in show
    print(self._show_string(n, truncate, vertical))
  File "/home/airflow/.local/lib/python3.10/site-packages/pyspark/sql/dataframe.py", line 976, in _show_string
    return self._jdf.showString(n, int_truncate, vertical)
  File "/home/airflow/.local/lib/python3.10/site-packages/py4j/java_gateway.py", line 1322, in __call__
    return_value = get_return_value(
  File "/home/airflow/.local/lib/python3.10/site-packages/pyspark/errors/exceptions/captured.py", line 179, in deco
    return f(*a, **kw)
  File "/home/airflow/.local/lib/python3.10/site-packages/py4j/protocol.py", line 334, in get_return_value
    raise Py4JError(
py4j.protocol.Py4JError: An error occurred while calling o183.showString

During handling of the above exception, another exception occurred:

Traceback (most recent call last):
  File "/home/airflow/.local/lib/python3.10/site-packages/py4j/clientserver.py", line 516, in send_command
    raise Py4JNetworkError("Answer from Java side is empty")
py4j.protocol.Py4JNetworkError: Answer from Java side is empty
[2025-06-08T14:53:58.988+0000] {clientserver.py:543} INFO - Closing down clientserver connection
[2025-06-08T14:53:58.989+0000] {java_gateway.py:1055} ERROR - Exception while sending command.
Traceback (most recent call last):
  File "/opt/airflow/scripts/pyspark_jobs/customer.py", line 68, in transform_customers_table
    raise e
  File "/opt/airflow/scripts/pyspark_jobs/customer.py", line 54, in transform_customers_table
    df_transformed.show(5, truncate=False)
  File "/home/airflow/.local/lib/python3.10/site-packages/pyspark/sql/dataframe.py", line 945, in show
    print(self._show_string(n, truncate, vertical))
  File "/home/airflow/.local/lib/python3.10/site-packages/pyspark/sql/dataframe.py", line 976, in _show_string
    return self._jdf.showString(n, int_truncate, vertical)
  File "/home/airflow/.local/lib/python3.10/site-packages/py4j/java_gateway.py", line 1322, in __call__
    return_value = get_return_value(
  File "/home/airflow/.local/lib/python3.10/site-packages/pyspark/errors/exceptions/captured.py", line 179, in deco
    return f(*a, **kw)
  File "/home/airflow/.local/lib/python3.10/site-packages/py4j/protocol.py", line 334, in get_return_value
    raise Py4JError(
py4j.protocol.Py4JError: An error occurred while calling o183.showString

During handling of the above exception, another exception occurred:

Traceback (most recent call last):
  File "/home/airflow/.local/lib/python3.10/site-packages/py4j/clientserver.py", line 516, in send_command
    raise Py4JNetworkError("Answer from Java side is empty")
py4j.protocol.Py4JNetworkError: Answer from Java side is empty

During handling of the above exception, another exception occurred:

Traceback (most recent call last):
  File "/home/airflow/.local/lib/python3.10/site-packages/py4j/java_gateway.py", line 1038, in send_command
    response = connection.send_command(command)
  File "/home/airflow/.local/lib/python3.10/site-packages/py4j/clientserver.py", line 539, in send_command
    raise Py4JNetworkError(
py4j.protocol.Py4JNetworkError: Error while sending or receiving
[2025-06-08T14:53:58.998+0000] {clientserver.py:543} INFO - Closing down clientserver connection
[2025-06-08T14:53:59.138+0000] {logging_mixin.py:188} WARNING - /home/airflow/.local/lib/python3.10/site-packages/pyspark/context.py:657 RuntimeWarning: Unable to cleanly shutdown Spark JVM process. It is possible that the process has crashed, been killed or may also be in a zombie state.
[2025-06-08T14:53:59.219+0000] {clientserver.py:543} INFO - Closing down clientserver connection
[2025-06-08T14:53:59.229+0000] {taskinstance.py:2698} ERROR - Task failed with exception
Traceback (most recent call last):
  File "/opt/airflow/scripts/pyspark_jobs/customer.py", line 68, in transform_customers_table
    raise e
  File "/opt/airflow/scripts/pyspark_jobs/customer.py", line 54, in transform_customers_table
    df_transformed.show(5, truncate=False)
  File "/home/airflow/.local/lib/python3.10/site-packages/pyspark/sql/dataframe.py", line 945, in show
    print(self._show_string(n, truncate, vertical))
  File "/home/airflow/.local/lib/python3.10/site-packages/pyspark/sql/dataframe.py", line 976, in _show_string
    return self._jdf.showString(n, int_truncate, vertical)
  File "/home/airflow/.local/lib/python3.10/site-packages/py4j/java_gateway.py", line 1322, in __call__
    return_value = get_return_value(
  File "/home/airflow/.local/lib/python3.10/site-packages/pyspark/errors/exceptions/captured.py", line 179, in deco
    return f(*a, **kw)
  File "/home/airflow/.local/lib/python3.10/site-packages/py4j/protocol.py", line 334, in get_return_value
    raise Py4JError(
py4j.protocol.Py4JError: An error occurred while calling o183.showString

During handling of the above exception, another exception occurred:

Traceback (most recent call last):
  File "/home/airflow/.local/lib/python3.10/site-packages/airflow/models/taskinstance.py", line 433, in _execute_task
    result = execute_callable(context=context, **execute_callable_kwargs)
  File "/home/airflow/.local/lib/python3.10/site-packages/airflow/decorators/base.py", line 241, in execute
    return_value = super().execute(context)
  File "/home/airflow/.local/lib/python3.10/site-packages/airflow/operators/python.py", line 199, in execute
    return_value = self.execute_callable()
  File "/home/airflow/.local/lib/python3.10/site-packages/airflow/operators/python.py", line 216, in execute_callable
    return self.python_callable(*self.op_args, **self.op_kwargs)
  File "/opt/airflow/dags/staging/customer_to_staging.py", line 99, in run_transformation_us
    transform_customers_table(
  File "/opt/airflow/scripts/pyspark_jobs/customer.py", line 70, in transform_customers_table
    spark.stop()
  File "/home/airflow/.local/lib/python3.10/site-packages/pyspark/sql/session.py", line 1799, in stop
    self._jvm.SparkSession.clearDefaultSession()
  File "/home/airflow/.local/lib/python3.10/site-packages/py4j/java_gateway.py", line 1712, in __getattr__
    answer = self._gateway_client.send_command(
  File "/home/airflow/.local/lib/python3.10/site-packages/py4j/java_gateway.py", line 1036, in send_command
    connection = self._get_connection()
  File "/home/airflow/.local/lib/python3.10/site-packages/py4j/clientserver.py", line 284, in _get_connection
    connection = self._create_new_connection()
  File "/home/airflow/.local/lib/python3.10/site-packages/py4j/clientserver.py", line 291, in _create_new_connection
    connection.connect_to_java_server()
  File "/home/airflow/.local/lib/python3.10/site-packages/py4j/clientserver.py", line 438, in connect_to_java_server
    self.socket.connect((self.java_address, self.java_port))
ConnectionRefusedError: [Errno 111] Connection refused
[2025-06-08T14:53:59.406+0000] {taskinstance.py:1138} INFO - Marking task as FAILED. dag_id=transform_customers_csv, task_id=run_transformation_us, execution_date=20250603T000000, start_date=20250608T145242, end_date=20250608T145359
[2025-06-08T14:53:59.684+0000] {standard_task_runner.py:107} ERROR - Failed to execute job 429 for task run_transformation_us ([Errno 111] Connection refused; 25789)
[2025-06-08T14:53:59.731+0000] {process_utils.py:79} INFO - Process psutil.Process(pid=25789, status='terminated', exitcode=1, started='14:52:43') (25789) terminated with exit code 1
[2025-06-08T14:53:59.743+0000] {process_utils.py:79} INFO - Process psutil.Process(pid=25813, status='terminated', started='14:52:44') (25813) terminated with exit code None
