[2025-06-11T12:30:47.742+0000] {taskinstance.py:1956} INFO - Dependencies all met for dep_context=non-requeueable deps ti=<TaskInstance: multi_region_transform_staging_v2.process_region_us.process_categories_us manual__2025-06-11T12:30:24.798327+00:00 [queued]>
[2025-06-11T12:30:47.761+0000] {taskinstance.py:1956} INFO - Dependencies all met for dep_context=requeueable deps ti=<TaskInstance: multi_region_transform_staging_v2.process_region_us.process_categories_us manual__2025-06-11T12:30:24.798327+00:00 [queued]>
[2025-06-11T12:30:47.762+0000] {taskinstance.py:2170} INFO - Starting attempt 1 of 2
[2025-06-11T12:30:47.792+0000] {taskinstance.py:2191} INFO - Executing <Task(_PythonDecoratedOperator): process_region_us.process_categories_us> on 2025-06-11 12:30:24.798327+00:00
[2025-06-11T12:30:47.803+0000] {standard_task_runner.py:60} INFO - Started process 50086 to run task
[2025-06-11T12:30:47.806+0000] {clientserver.py:543} INFO - Closing down clientserver connection
[2025-06-11T12:30:47.813+0000] {standard_task_runner.py:87} INFO - Running: ['airflow', 'tasks', 'run', 'multi_region_transform_staging_v2', 'process_region_us.process_categories_us', 'manual__2025-06-11T12:30:24.798327+00:00', '--job-id', '1739', '--raw', '--subdir', 'DAGS_FOLDER/master_dag.py', '--cfg-path', '/tmp/tmpfh3oww7l']
[2025-06-11T12:30:47.815+0000] {standard_task_runner.py:88} INFO - Job 1739: Subtask process_region_us.process_categories_us
[2025-06-11T12:30:47.933+0000] {task_command.py:423} INFO - Running <TaskInstance: multi_region_transform_staging_v2.process_region_us.process_categories_us manual__2025-06-11T12:30:24.798327+00:00 [running]> on host 8b0a421f0af7
[2025-06-11T12:30:48.108+0000] {clientserver.py:505} INFO - Error while sending or receiving.
Traceback (most recent call last):
  File "/home/airflow/.local/lib/python3.10/site-packages/py4j/clientserver.py", line 503, in send_command
    self.socket.sendall(command.encode("utf-8"))
ConnectionResetError: [Errno 104] Connection reset by peer
[2025-06-11T12:30:48.110+0000] {clientserver.py:543} INFO - Closing down clientserver connection
[2025-06-11T12:30:48.110+0000] {java_gateway.py:1052} INFO - Exception while sending command.
Traceback (most recent call last):
  File "/home/airflow/.local/lib/python3.10/site-packages/py4j/clientserver.py", line 503, in send_command
    self.socket.sendall(command.encode("utf-8"))
ConnectionResetError: [Errno 104] Connection reset by peer

During handling of the above exception, another exception occurred:

Traceback (most recent call last):
  File "/home/airflow/.local/lib/python3.10/site-packages/py4j/java_gateway.py", line 1038, in send_command
    response = connection.send_command(command)
  File "/home/airflow/.local/lib/python3.10/site-packages/py4j/clientserver.py", line 506, in send_command
    raise Py4JNetworkError(
py4j.protocol.Py4JNetworkError: Error while sending
[2025-06-11T12:30:48.119+0000] {clientserver.py:543} INFO - Closing down clientserver connection
[2025-06-11T12:30:48.126+0000] {taskinstance.py:2480} INFO - Exporting env vars: AIRFLOW_CTX_DAG_OWNER='data-team' AIRFLOW_CTX_DAG_ID='multi_region_transform_staging_v2' AIRFLOW_CTX_TASK_ID='process_region_us.process_categories_us' AIRFLOW_CTX_EXECUTION_DATE='2025-06-11T12:30:24.798327+00:00' AIRFLOW_CTX_TRY_NUMBER='1' AIRFLOW_CTX_DAG_RUN_ID='manual__2025-06-11T12:30:24.798327+00:00'
[2025-06-11T12:30:48.127+0000] {taskinstance.py:2698} ERROR - Task failed with exception
Traceback (most recent call last):
  File "/home/airflow/.local/lib/python3.10/site-packages/airflow/models/taskinstance.py", line 433, in _execute_task
    result = execute_callable(context=context, **execute_callable_kwargs)
  File "/home/airflow/.local/lib/python3.10/site-packages/airflow/decorators/base.py", line 241, in execute
    return_value = super().execute(context)
  File "/home/airflow/.local/lib/python3.10/site-packages/airflow/operators/python.py", line 199, in execute
    return_value = self.execute_callable()
  File "/home/airflow/.local/lib/python3.10/site-packages/airflow/operators/python.py", line 216, in execute_callable
    return self.python_callable(*self.op_args, **self.op_kwargs)
  File "/opt/airflow/dags/master_dag.py", line 188, in process_table
    spark = get_spark_session()
TypeError: get_spark_session() missing 1 required positional argument: 'app_name'
[2025-06-11T12:30:48.156+0000] {taskinstance.py:1138} INFO - Marking task as UP_FOR_RETRY. dag_id=multi_region_transform_staging_v2, task_id=process_region_us.process_categories_us, execution_date=20250611T123024, start_date=20250611T123047, end_date=20250611T123048
[2025-06-11T12:30:48.184+0000] {standard_task_runner.py:107} ERROR - Failed to execute job 1739 for task process_region_us.process_categories_us (get_spark_session() missing 1 required positional argument: 'app_name'; 50086)
[2025-06-11T12:30:48.225+0000] {local_task_job_runner.py:234} INFO - Task exited with return code 1
[2025-06-11T12:30:48.400+0000] {taskinstance.py:3280} INFO - 0 downstream tasks scheduled from follow-on schedule check
