[2025-06-10T19:11:47.156+0000] {taskinstance.py:1956} INFO - Dependencies all met for dep_context=non-requeueable deps ti=<TaskInstance: geography_to_snowflake.Load_geography_method manual__2025-06-10T19:10:25.731354+00:00 [queued]>
[2025-06-10T19:11:47.167+0000] {taskinstance.py:1956} INFO - Dependencies all met for dep_context=requeueable deps ti=<TaskInstance: geography_to_snowflake.Load_geography_method manual__2025-06-10T19:10:25.731354+00:00 [queued]>
[2025-06-10T19:11:47.168+0000] {taskinstance.py:2170} INFO - Starting attempt 2 of 2
[2025-06-10T19:11:47.186+0000] {taskinstance.py:2191} INFO - Executing <Task(_PythonDecoratedOperator): Load_geography_method> on 2025-06-10 19:10:25.731354+00:00
[2025-06-10T19:11:47.195+0000] {standard_task_runner.py:60} INFO - Started process 11619 to run task
[2025-06-10T19:11:47.198+0000] {standard_task_runner.py:87} INFO - Running: ['airflow', 'tasks', 'run', 'geography_to_snowflake', 'Load_geography_method', 'manual__2025-06-10T19:10:25.731354+00:00', '--job-id', '1119', '--raw', '--subdir', 'DAGS_FOLDER/star/geography.py', '--cfg-path', '/tmp/tmp544g45z8']
[2025-06-10T19:11:47.201+0000] {standard_task_runner.py:88} INFO - Job 1119: Subtask Load_geography_method
[2025-06-10T19:11:47.277+0000] {task_command.py:423} INFO - Running <TaskInstance: geography_to_snowflake.Load_geography_method manual__2025-06-10T19:10:25.731354+00:00 [running]> on host 9820768629fb
[2025-06-10T19:11:47.402+0000] {taskinstance.py:2480} INFO - Exporting env vars: AIRFLOW_CTX_DAG_OWNER='data-team' AIRFLOW_CTX_DAG_ID='geography_to_snowflake' AIRFLOW_CTX_TASK_ID='Load_geography_method' AIRFLOW_CTX_EXECUTION_DATE='2025-06-10T19:10:25.731354+00:00' AIRFLOW_CTX_TRY_NUMBER='2' AIRFLOW_CTX_DAG_RUN_ID='manual__2025-06-10T19:10:25.731354+00:00'
[2025-06-10T19:12:09.493+0000] {logging_mixin.py:188} INFO - Error processing geography data: An error occurred while calling o45.save.
: net.snowflake.client.jdbc.SnowflakeSQLException: SQL compilation error:
syntax error line 1 at position 44 unexpected ')'.
	at net.snowflake.client.jdbc.SnowflakeUtil.checkErrorAndThrowExceptionSub(SnowflakeUtil.java:127)
	at net.snowflake.client.jdbc.SnowflakeUtil.checkErrorAndThrowException(SnowflakeUtil.java:67)
	at net.snowflake.client.core.StmtUtil.pollForOutput(StmtUtil.java:456)
	at net.snowflake.client.core.StmtUtil.execute(StmtUtil.java:366)
	at net.snowflake.client.core.SFStatement.executeHelper(SFStatement.java:468)
	at net.snowflake.client.core.SFStatement.executeQueryInternal(SFStatement.java:196)
	at net.snowflake.client.core.SFStatement.executeQuery(SFStatement.java:133)
	at net.snowflake.client.core.SFStatement.execute(SFStatement.java:746)
	at net.snowflake.client.core.SFStatement.execute(SFStatement.java:656)
	at net.snowflake.client.jdbc.SnowflakeStatementV1.executeQueryInternal(SnowflakeStatementV1.java:236)
	at net.snowflake.client.jdbc.SnowflakePreparedStatementV1.executeQuery(SnowflakePreparedStatementV1.java:118)
	at net.snowflake.spark.snowflake.JDBCWrapper.$anonfun$executePreparedQueryInterruptibly$1(SnowflakeJDBCWrapper.scala:331)
	at net.snowflake.spark.snowflake.JDBCWrapper.$anonfun$executeInterruptibly$2(SnowflakeJDBCWrapper.scala:378)
	at scala.concurrent.Future$.$anonfun$apply$1(Future.scala:659)
	at scala.util.Success.$anonfun$map$1(Try.scala:255)
	at scala.util.Success.map(Try.scala:213)
	at scala.concurrent.Future.$anonfun$map$1(Future.scala:292)
	at scala.concurrent.impl.Promise.liftedTree1$1(Promise.scala:33)
	at scala.concurrent.impl.Promise.$anonfun$transform$1(Promise.scala:33)
	at scala.concurrent.impl.CallbackRunnable.run(Promise.scala:64)
	at java.base/java.util.concurrent.ThreadPoolExecutor.runWorker(ThreadPoolExecutor.java:1128)
	at java.base/java.util.concurrent.ThreadPoolExecutor$Worker.run(ThreadPoolExecutor.java:628)
	at java.base/java.lang.Thread.run(Thread.java:829)
[2025-06-10T19:12:09.494+0000] {taskinstance.py:2698} ERROR - Task failed with exception
Traceback (most recent call last):
  File "/home/airflow/.local/lib/python3.10/site-packages/airflow/models/taskinstance.py", line 433, in _execute_task
    result = execute_callable(context=context, **execute_callable_kwargs)
  File "/home/airflow/.local/lib/python3.10/site-packages/airflow/decorators/base.py", line 241, in execute
    return_value = super().execute(context)
  File "/home/airflow/.local/lib/python3.10/site-packages/airflow/operators/python.py", line 199, in execute
    return_value = self.execute_callable()
  File "/home/airflow/.local/lib/python3.10/site-packages/airflow/operators/python.py", line 216, in execute_callable
    return self.python_callable(*self.op_args, **self.op_kwargs)
  File "/opt/airflow/dags/star/geography.py", line 61, in Load_geography_method
    raise e
  File "/opt/airflow/dags/star/geography.py", line 56, in Load_geography_method
    upsert_geography_from_csv_spark('/opt/airflow/data/lookup/geography.csv')
  File "/opt/airflow/scripts/star_load/geography.py", line 61, in upsert_geography_from_csv_spark
    .save()
  File "/home/airflow/.local/lib/python3.10/site-packages/pyspark/sql/readwriter.py", line 1461, in save
    self._jwrite.save()
  File "/home/airflow/.local/lib/python3.10/site-packages/py4j/java_gateway.py", line 1322, in __call__
    return_value = get_return_value(
  File "/home/airflow/.local/lib/python3.10/site-packages/pyspark/errors/exceptions/captured.py", line 179, in deco
    return f(*a, **kw)
  File "/home/airflow/.local/lib/python3.10/site-packages/py4j/protocol.py", line 326, in get_return_value
    raise Py4JJavaError(
py4j.protocol.Py4JJavaError: An error occurred while calling o45.save.
: net.snowflake.client.jdbc.SnowflakeSQLException: SQL compilation error:
syntax error line 1 at position 44 unexpected ')'.
	at net.snowflake.client.jdbc.SnowflakeUtil.checkErrorAndThrowExceptionSub(SnowflakeUtil.java:127)
	at net.snowflake.client.jdbc.SnowflakeUtil.checkErrorAndThrowException(SnowflakeUtil.java:67)
	at net.snowflake.client.core.StmtUtil.pollForOutput(StmtUtil.java:456)
	at net.snowflake.client.core.StmtUtil.execute(StmtUtil.java:366)
	at net.snowflake.client.core.SFStatement.executeHelper(SFStatement.java:468)
	at net.snowflake.client.core.SFStatement.executeQueryInternal(SFStatement.java:196)
	at net.snowflake.client.core.SFStatement.executeQuery(SFStatement.java:133)
	at net.snowflake.client.core.SFStatement.execute(SFStatement.java:746)
	at net.snowflake.client.core.SFStatement.execute(SFStatement.java:656)
	at net.snowflake.client.jdbc.SnowflakeStatementV1.executeQueryInternal(SnowflakeStatementV1.java:236)
	at net.snowflake.client.jdbc.SnowflakePreparedStatementV1.executeQuery(SnowflakePreparedStatementV1.java:118)
	at net.snowflake.spark.snowflake.JDBCWrapper.$anonfun$executePreparedQueryInterruptibly$1(SnowflakeJDBCWrapper.scala:331)
	at net.snowflake.spark.snowflake.JDBCWrapper.$anonfun$executeInterruptibly$2(SnowflakeJDBCWrapper.scala:378)
	at scala.concurrent.Future$.$anonfun$apply$1(Future.scala:659)
	at scala.util.Success.$anonfun$map$1(Try.scala:255)
	at scala.util.Success.map(Try.scala:213)
	at scala.concurrent.Future.$anonfun$map$1(Future.scala:292)
	at scala.concurrent.impl.Promise.liftedTree1$1(Promise.scala:33)
	at scala.concurrent.impl.Promise.$anonfun$transform$1(Promise.scala:33)
	at scala.concurrent.impl.CallbackRunnable.run(Promise.scala:64)
	at java.base/java.util.concurrent.ThreadPoolExecutor.runWorker(ThreadPoolExecutor.java:1128)
	at java.base/java.util.concurrent.ThreadPoolExecutor$Worker.run(ThreadPoolExecutor.java:628)
	at java.base/java.lang.Thread.run(Thread.java:829)

[2025-06-10T19:12:09.513+0000] {taskinstance.py:1138} INFO - Marking task as FAILED. dag_id=geography_to_snowflake, task_id=Load_geography_method, execution_date=20250610T191025, start_date=20250610T191147, end_date=20250610T191209
[2025-06-10T19:12:09.530+0000] {standard_task_runner.py:107} ERROR - Failed to execute job 1119 for task Load_geography_method (An error occurred while calling o45.save.
: net.snowflake.client.jdbc.SnowflakeSQLException: SQL compilation error:
syntax error line 1 at position 44 unexpected ')'.
	at net.snowflake.client.jdbc.SnowflakeUtil.checkErrorAndThrowExceptionSub(SnowflakeUtil.java:127)
	at net.snowflake.client.jdbc.SnowflakeUtil.checkErrorAndThrowException(SnowflakeUtil.java:67)
	at net.snowflake.client.core.StmtUtil.pollForOutput(StmtUtil.java:456)
	at net.snowflake.client.core.StmtUtil.execute(StmtUtil.java:366)
	at net.snowflake.client.core.SFStatement.executeHelper(SFStatement.java:468)
	at net.snowflake.client.core.SFStatement.executeQueryInternal(SFStatement.java:196)
	at net.snowflake.client.core.SFStatement.executeQuery(SFStatement.java:133)
	at net.snowflake.client.core.SFStatement.execute(SFStatement.java:746)
	at net.snowflake.client.core.SFStatement.execute(SFStatement.java:656)
	at net.snowflake.client.jdbc.SnowflakeStatementV1.executeQueryInternal(SnowflakeStatementV1.java:236)
	at net.snowflake.client.jdbc.SnowflakePreparedStatementV1.executeQuery(SnowflakePreparedStatementV1.java:118)
	at net.snowflake.spark.snowflake.JDBCWrapper.$anonfun$executePreparedQueryInterruptibly$1(SnowflakeJDBCWrapper.scala:331)
	at net.snowflake.spark.snowflake.JDBCWrapper.$anonfun$executeInterruptibly$2(SnowflakeJDBCWrapper.scala:378)
	at scala.concurrent.Future$.$anonfun$apply$1(Future.scala:659)
	at scala.util.Success.$anonfun$map$1(Try.scala:255)
	at scala.util.Success.map(Try.scala:213)
	at scala.concurrent.Future.$anonfun$map$1(Future.scala:292)
	at scala.concurrent.impl.Promise.liftedTree1$1(Promise.scala:33)
	at scala.concurrent.impl.Promise.$anonfun$transform$1(Promise.scala:33)
	at scala.concurrent.impl.CallbackRunnable.run(Promise.scala:64)
	at java.base/java.util.concurrent.ThreadPoolExecutor.runWorker(ThreadPoolExecutor.java:1128)
	at java.base/java.util.concurrent.ThreadPoolExecutor$Worker.run(ThreadPoolExecutor.java:628)
	at java.base/java.lang.Thread.run(Thread.java:829)
; 11619)
[2025-06-10T19:12:09.550+0000] {local_task_job_runner.py:234} INFO - Task exited with return code 1
[2025-06-10T19:12:09.571+0000] {taskinstance.py:3280} INFO - 0 downstream tasks scheduled from follow-on schedule check
