[2025-06-04T08:18:28.254+0000] {taskinstance.py:1956} INFO - Dependencies all met for dep_context=non-requeueable deps ti=<TaskInstance: store_exchange_rates_to_snowflake.run_exchange_script manual__2025-06-04T08:18:27.092135+00:00 [queued]>
[2025-06-04T08:18:28.263+0000] {taskinstance.py:1956} INFO - Dependencies all met for dep_context=requeueable deps ti=<TaskInstance: store_exchange_rates_to_snowflake.run_exchange_script manual__2025-06-04T08:18:27.092135+00:00 [queued]>
[2025-06-04T08:18:28.263+0000] {taskinstance.py:2170} INFO - Starting attempt 1 of 1
[2025-06-04T08:18:28.273+0000] {taskinstance.py:2191} INFO - Executing <Task(_PythonDecoratedOperator): run_exchange_script> on 2025-06-04 08:18:27.092135+00:00
[2025-06-04T08:18:28.279+0000] {standard_task_runner.py:60} INFO - Started process 971 to run task
[2025-06-04T08:18:28.281+0000] {standard_task_runner.py:87} INFO - Running: ['airflow', 'tasks', 'run', 'store_exchange_rates_to_snowflake', 'run_exchange_script', 'manual__2025-06-04T08:18:27.092135+00:00', '--job-id', '15', '--raw', '--subdir', 'DAGS_FOLDER/asia/curr_exchange_to_snowflake.py', '--cfg-path', '/tmp/tmpxfkj8dfz']
[2025-06-04T08:18:28.282+0000] {standard_task_runner.py:88} INFO - Job 15: Subtask run_exchange_script
[2025-06-04T08:18:28.338+0000] {task_command.py:423} INFO - Running <TaskInstance: store_exchange_rates_to_snowflake.run_exchange_script manual__2025-06-04T08:18:27.092135+00:00 [running]> on host bfc87edc9706
[2025-06-04T08:18:28.429+0000] {taskinstance.py:2480} INFO - Exporting env vars: AIRFLOW_CTX_DAG_OWNER='airflow' AIRFLOW_CTX_DAG_ID='store_exchange_rates_to_snowflake' AIRFLOW_CTX_TASK_ID='run_exchange_script' AIRFLOW_CTX_EXECUTION_DATE='2025-06-04T08:18:27.092135+00:00' AIRFLOW_CTX_TRY_NUMBER='1' AIRFLOW_CTX_DAG_RUN_ID='manual__2025-06-04T08:18:27.092135+00:00'
[2025-06-04T08:18:29.977+0000] {taskinstance.py:2698} ERROR - Task failed with exception
Traceback (most recent call last):
  File "/home/airflow/.local/lib/python3.10/site-packages/airflow/models/taskinstance.py", line 433, in _execute_task
    result = execute_callable(context=context, **execute_callable_kwargs)
  File "/home/airflow/.local/lib/python3.10/site-packages/airflow/decorators/base.py", line 241, in execute
    return_value = super().execute(context)
  File "/home/airflow/.local/lib/python3.10/site-packages/airflow/operators/python.py", line 199, in execute
    return_value = self.execute_callable()
  File "/home/airflow/.local/lib/python3.10/site-packages/airflow/operators/python.py", line 216, in execute_callable
    return self.python_callable(*self.op_args, **self.op_kwargs)
  File "/opt/airflow/dags/asia/curr_exchange_to_snowflake.py", line 31, in run_exchange_script
    raise RuntimeError(f"Script failed: {result.stderr}")
RuntimeError: Script failed: Traceback (most recent call last):
  File "/opt/airflow/scripts/pyspark_jobs/exchange_rate.py", line 65, in <module>
    store_rates_to_snowflake(rates)
  File "/opt/airflow/scripts/pyspark_jobs/exchange_rate.py", line 33, in store_rates_to_snowflake
    conn = snowflake.connector.connect(**SNOWFLAKE_CONFIG)
  File "/home/airflow/.local/lib/python3.10/site-packages/snowflake/connector/__init__.py", line 54, in Connect
    return SnowflakeConnection(**kwargs)
  File "/home/airflow/.local/lib/python3.10/site-packages/snowflake/connector/connection.py", line 548, in __init__
    self.connect(**kwargs)
  File "/home/airflow/.local/lib/python3.10/site-packages/snowflake/connector/connection.py", line 862, in connect
    self.__config(**kwargs)
  File "/home/airflow/.local/lib/python3.10/site-packages/snowflake/connector/connection.py", line 1433, in __config
    Error.errorhandler_wrapper(
  File "/home/airflow/.local/lib/python3.10/site-packages/snowflake/connector/errors.py", line 279, in errorhandler_wrapper
    handed_over = Error.hand_to_other_handler(
  File "/home/airflow/.local/lib/python3.10/site-packages/snowflake/connector/errors.py", line 337, in hand_to_other_handler
    connection.errorhandler(connection, cursor, error_class, error_value)
  File "/home/airflow/.local/lib/python3.10/site-packages/snowflake/connector/errors.py", line 210, in default_errorhandler
    raise error_class(
snowflake.connector.errors.ProgrammingError: 251005: User is empty

[2025-06-04T08:18:29.988+0000] {taskinstance.py:1138} INFO - Marking task as FAILED. dag_id=store_exchange_rates_to_snowflake, task_id=run_exchange_script, execution_date=20250604T081827, start_date=20250604T081828, end_date=20250604T081829
[2025-06-04T08:18:30.000+0000] {standard_task_runner.py:107} ERROR - Failed to execute job 15 for task run_exchange_script (Script failed: Traceback (most recent call last):
  File "/opt/airflow/scripts/pyspark_jobs/exchange_rate.py", line 65, in <module>
    store_rates_to_snowflake(rates)
  File "/opt/airflow/scripts/pyspark_jobs/exchange_rate.py", line 33, in store_rates_to_snowflake
    conn = snowflake.connector.connect(**SNOWFLAKE_CONFIG)
  File "/home/airflow/.local/lib/python3.10/site-packages/snowflake/connector/__init__.py", line 54, in Connect
    return SnowflakeConnection(**kwargs)
  File "/home/airflow/.local/lib/python3.10/site-packages/snowflake/connector/connection.py", line 548, in __init__
    self.connect(**kwargs)
  File "/home/airflow/.local/lib/python3.10/site-packages/snowflake/connector/connection.py", line 862, in connect
    self.__config(**kwargs)
  File "/home/airflow/.local/lib/python3.10/site-packages/snowflake/connector/connection.py", line 1433, in __config
    Error.errorhandler_wrapper(
  File "/home/airflow/.local/lib/python3.10/site-packages/snowflake/connector/errors.py", line 279, in errorhandler_wrapper
    handed_over = Error.hand_to_other_handler(
  File "/home/airflow/.local/lib/python3.10/site-packages/snowflake/connector/errors.py", line 337, in hand_to_other_handler
    connection.errorhandler(connection, cursor, error_class, error_value)
  File "/home/airflow/.local/lib/python3.10/site-packages/snowflake/connector/errors.py", line 210, in default_errorhandler
    raise error_class(
snowflake.connector.errors.ProgrammingError: 251005: User is empty
; 971)
[2025-06-04T08:18:30.018+0000] {local_task_job_runner.py:234} INFO - Task exited with return code 1
[2025-06-04T08:18:30.037+0000] {taskinstance.py:3280} INFO - 0 downstream tasks scheduled from follow-on schedule check
