[2025-06-09T06:56:02.398+0000] {taskinstance.py:1956} INFO - Dependencies all met for dep_context=non-requeueable deps ti=<TaskInstance: multi_region_processor_alternative.process_categories_eu manual__2025-06-09T06:55:54.379533+00:00 [queued]>
[2025-06-09T06:56:02.415+0000] {taskinstance.py:1956} INFO - Dependencies all met for dep_context=requeueable deps ti=<TaskInstance: multi_region_processor_alternative.process_categories_eu manual__2025-06-09T06:55:54.379533+00:00 [queued]>
[2025-06-09T06:56:02.416+0000] {taskinstance.py:2170} INFO - Starting attempt 1 of 2
[2025-06-09T06:56:02.438+0000] {taskinstance.py:2191} INFO - Executing <Task(_PythonDecoratedOperator): process_categories_eu> on 2025-06-09 06:55:54.379533+00:00
[2025-06-09T06:56:02.447+0000] {standard_task_runner.py:60} INFO - Started process 42028 to run task
[2025-06-09T06:56:02.451+0000] {standard_task_runner.py:87} INFO - Running: ['airflow', 'tasks', 'run', 'multi_region_processor_alternative', 'process_categories_eu', 'manual__2025-06-09T06:55:54.379533+00:00', '--job-id', '41', '--raw', '--subdir', 'DAGS_FOLDER/dag_run.py', '--cfg-path', '/tmp/tmpc6w29hbu']
[2025-06-09T06:56:02.454+0000] {standard_task_runner.py:88} INFO - Job 41: Subtask process_categories_eu
[2025-06-09T06:56:02.484+0000] {logging_mixin.py:188} WARNING - /home/airflow/.local/lib/python3.10/site-packages/airflow/settings.py:194 DeprecationWarning: The sql_alchemy_conn option in [core] has been moved to the sql_alchemy_conn option in [database] - the old setting has been used, but please update your config.
[2025-06-09T06:56:02.558+0000] {task_command.py:423} INFO - Running <TaskInstance: multi_region_processor_alternative.process_categories_eu manual__2025-06-09T06:55:54.379533+00:00 [running]> on host afcdbcf38bc0
[2025-06-09T06:56:02.755+0000] {taskinstance.py:2480} INFO - Exporting env vars: AIRFLOW_CTX_DAG_OWNER='data-team' AIRFLOW_CTX_DAG_ID='multi_region_processor_alternative' AIRFLOW_CTX_TASK_ID='process_categories_eu' AIRFLOW_CTX_EXECUTION_DATE='2025-06-09T06:55:54.379533+00:00' AIRFLOW_CTX_TRY_NUMBER='1' AIRFLOW_CTX_DAG_RUN_ID='manual__2025-06-09T06:55:54.379533+00:00'
[2025-06-09T06:56:09.379+0000] {logging_mixin.py:188} INFO - Error processing categories for eu: [JAVA_GATEWAY_EXITED] Java gateway process exited before sending its port number.
[2025-06-09T06:56:09.380+0000] {taskinstance.py:2698} ERROR - Task failed with exception
Traceback (most recent call last):
  File "/opt/airflow/dags/dag_run.py", line 129, in process_table
    spark = get_spark_session(f"Process_{table}_{region}_{load_date}")
  File "/opt/airflow/dags/dag_run.py", line 115, in get_spark_session
    .getOrCreate()
  File "/home/airflow/.local/lib/python3.10/site-packages/pyspark/sql/session.py", line 497, in getOrCreate
    sc = SparkContext.getOrCreate(sparkConf)
  File "/home/airflow/.local/lib/python3.10/site-packages/pyspark/context.py", line 515, in getOrCreate
    SparkContext(conf=conf or SparkConf())
  File "/home/airflow/.local/lib/python3.10/site-packages/pyspark/context.py", line 201, in __init__
    SparkContext._ensure_initialized(self, gateway=gateway, conf=conf)
  File "/home/airflow/.local/lib/python3.10/site-packages/pyspark/context.py", line 436, in _ensure_initialized
    SparkContext._gateway = gateway or launch_gateway(conf)
  File "/home/airflow/.local/lib/python3.10/site-packages/pyspark/java_gateway.py", line 107, in launch_gateway
    raise PySparkRuntimeError(
pyspark.errors.exceptions.base.PySparkRuntimeError: [JAVA_GATEWAY_EXITED] Java gateway process exited before sending its port number.

During handling of the above exception, another exception occurred:

Traceback (most recent call last):
  File "/home/airflow/.local/lib/python3.10/site-packages/airflow/models/taskinstance.py", line 433, in _execute_task
    result = execute_callable(context=context, **execute_callable_kwargs)
  File "/home/airflow/.local/lib/python3.10/site-packages/airflow/decorators/base.py", line 241, in execute
    return_value = super().execute(context)
  File "/home/airflow/.local/lib/python3.10/site-packages/airflow/operators/python.py", line 199, in execute
    return_value = self.execute_callable()
  File "/home/airflow/.local/lib/python3.10/site-packages/airflow/operators/python.py", line 216, in execute_callable
    return self.python_callable(*self.op_args, **self.op_kwargs)
  File "/opt/airflow/dags/dag_run.py", line 176, in process_table
    raise Exception(error_msg)
Exception: Error processing categories for eu: [JAVA_GATEWAY_EXITED] Java gateway process exited before sending its port number.
[2025-06-09T06:56:09.409+0000] {taskinstance.py:1138} INFO - Marking task as UP_FOR_RETRY. dag_id=multi_region_processor_alternative, task_id=process_categories_eu, execution_date=20250609T065554, start_date=20250609T065602, end_date=20250609T065609
[2025-06-09T06:56:09.435+0000] {standard_task_runner.py:107} ERROR - Failed to execute job 41 for task process_categories_eu (Error processing categories for eu: [JAVA_GATEWAY_EXITED] Java gateway process exited before sending its port number.; 42028)
[2025-06-09T06:56:09.458+0000] {local_task_job_runner.py:234} INFO - Task exited with return code 1
[2025-06-09T06:56:09.511+0000] {taskinstance.py:3280} INFO - 0 downstream tasks scheduled from follow-on schedule check
