[2025-06-11T19:04:33.848+0000] {taskinstance.py:1956} INFO - Dependencies all met for dep_context=non-requeueable deps ti=<TaskInstance: load_to_star_schema_fact.star_merge_group.star_fact_marketing_performance manual__2025-06-11T19:03:27.889937+00:00 [queued]>
[2025-06-11T19:04:33.857+0000] {taskinstance.py:1956} INFO - Dependencies all met for dep_context=requeueable deps ti=<TaskInstance: load_to_star_schema_fact.star_merge_group.star_fact_marketing_performance manual__2025-06-11T19:03:27.889937+00:00 [queued]>
[2025-06-11T19:04:33.857+0000] {taskinstance.py:2170} INFO - Starting attempt 2 of 2
[2025-06-11T19:04:33.873+0000] {taskinstance.py:2191} INFO - Executing <Task(_PythonDecoratedOperator): star_merge_group.star_fact_marketing_performance> on 2025-06-11 19:03:27.889937+00:00
[2025-06-11T19:04:33.885+0000] {standard_task_runner.py:60} INFO - Started process 54274 to run task
[2025-06-11T19:04:33.887+0000] {standard_task_runner.py:87} INFO - Running: ['airflow', 'tasks', 'run', 'load_to_star_schema_fact', 'star_merge_group.star_fact_marketing_performance', 'manual__2025-06-11T19:03:27.889937+00:00', '--job-id', '888', '--raw', '--subdir', 'DAGS_FOLDER/star/master_fact.py', '--cfg-path', '/tmp/tmp0tfoelcv']
[2025-06-11T19:04:33.888+0000] {standard_task_runner.py:88} INFO - Job 888: Subtask star_merge_group.star_fact_marketing_performance
[2025-06-11T19:04:33.947+0000] {task_command.py:423} INFO - Running <TaskInstance: load_to_star_schema_fact.star_merge_group.star_fact_marketing_performance manual__2025-06-11T19:03:27.889937+00:00 [running]> on host 5950010ae7c1
[2025-06-11T19:04:34.050+0000] {taskinstance.py:2480} INFO - Exporting env vars: AIRFLOW_CTX_DAG_OWNER='data-team' AIRFLOW_CTX_DAG_ID='load_to_star_schema_fact' AIRFLOW_CTX_TASK_ID='star_merge_group.star_fact_marketing_performance' AIRFLOW_CTX_EXECUTION_DATE='2025-06-11T19:03:27.889937+00:00' AIRFLOW_CTX_TRY_NUMBER='2' AIRFLOW_CTX_DAG_RUN_ID='manual__2025-06-11T19:03:27.889937+00:00'
[2025-06-11T19:04:34.052+0000] {connection.py:486} INFO - Snowflake Connector for Python Version: 3.15.0, Python Version: 3.10.13, Platform: Linux-6.11.0-26-generic-x86_64-with-glibc2.36
[2025-06-11T19:04:34.052+0000] {connection.py:1391} INFO - Connecting to GLOBAL Snowflake domain
[2025-06-11T19:04:35.567+0000] {logging_mixin.py:188} INFO - Successfully connected to Snowflake via snowflake.connector.
[2025-06-11T19:04:35.567+0000] {logging_mixin.py:188} INFO - Running merge for marketing_performance...
[2025-06-11T19:04:35.987+0000] {logging_mixin.py:188} INFO - Error running merge for marketing_performance: 001003 (42000): 01bcf6b8-0305-9440-0008-654b00122fea: SQL compilation error:
syntax error line 28 at position 33 unexpected 'IS'.
syntax error line 110 at position 4 unexpected ')'.
[2025-06-11T19:04:36.626+0000] {taskinstance.py:2698} ERROR - Task failed with exception
Traceback (most recent call last):
  File "/home/airflow/.local/lib/python3.10/site-packages/airflow/models/taskinstance.py", line 433, in _execute_task
    result = execute_callable(context=context, **execute_callable_kwargs)
  File "/home/airflow/.local/lib/python3.10/site-packages/airflow/decorators/base.py", line 241, in execute
    return_value = super().execute(context)
  File "/home/airflow/.local/lib/python3.10/site-packages/airflow/operators/python.py", line 199, in execute
    return_value = self.execute_callable()
  File "/home/airflow/.local/lib/python3.10/site-packages/airflow/operators/python.py", line 216, in execute_callable
    return self.python_callable(*self.op_args, **self.op_kwargs)
  File "/opt/airflow/dags/star/master_fact.py", line 96, in merge_table
    run_merge_query(t)
  File "/opt/airflow/dags/star/master_fact.py", line 81, in run_merge_query
    cursor.execute(merge_sql)
  File "/home/airflow/.local/lib/python3.10/site-packages/snowflake/connector/cursor.py", line 1134, in execute
    Error.errorhandler_wrapper(self.connection, self, error_class, errvalue)
  File "/home/airflow/.local/lib/python3.10/site-packages/snowflake/connector/errors.py", line 279, in errorhandler_wrapper
    handed_over = Error.hand_to_other_handler(
  File "/home/airflow/.local/lib/python3.10/site-packages/snowflake/connector/errors.py", line 334, in hand_to_other_handler
    cursor.errorhandler(connection, cursor, error_class, error_value)
  File "/home/airflow/.local/lib/python3.10/site-packages/snowflake/connector/errors.py", line 210, in default_errorhandler
    raise error_class(
snowflake.connector.errors.ProgrammingError: 001003 (42000): 01bcf6b8-0305-9440-0008-654b00122fea: SQL compilation error:
syntax error line 28 at position 33 unexpected 'IS'.
syntax error line 110 at position 4 unexpected ')'.
[2025-06-11T19:04:36.638+0000] {taskinstance.py:1138} INFO - Marking task as FAILED. dag_id=load_to_star_schema_fact, task_id=star_merge_group.star_fact_marketing_performance, execution_date=20250611T190327, start_date=20250611T190433, end_date=20250611T190436
[2025-06-11T19:04:36.651+0000] {standard_task_runner.py:107} ERROR - Failed to execute job 888 for task star_merge_group.star_fact_marketing_performance (001003 (42000): 01bcf6b8-0305-9440-0008-654b00122fea: SQL compilation error:
syntax error line 28 at position 33 unexpected 'IS'.
syntax error line 110 at position 4 unexpected ')'.; 54274)
[2025-06-11T19:04:36.668+0000] {local_task_job_runner.py:234} INFO - Task exited with return code 1
[2025-06-11T19:04:36.687+0000] {taskinstance.py:3280} INFO - 0 downstream tasks scheduled from follow-on schedule check
