[2025-06-08T14:53:54.764+0000] {taskinstance.py:1956} INFO - Dependencies all met for dep_context=non-requeueable deps ti=<TaskInstance: transform_customers_csv.run_transformation_us manual__2025-06-08T14:52:40.167851+00:00 [queued]>
[2025-06-08T14:53:54.820+0000] {taskinstance.py:1956} INFO - Dependencies all met for dep_context=requeueable deps ti=<TaskInstance: transform_customers_csv.run_transformation_us manual__2025-06-08T14:52:40.167851+00:00 [queued]>
[2025-06-08T14:53:54.821+0000] {taskinstance.py:2170} INFO - Starting attempt 1 of 1
[2025-06-08T14:53:54.927+0000] {taskinstance.py:2191} INFO - Executing <Task(_PythonDecoratedOperator): run_transformation_us> on 2025-06-08 14:52:40.167851+00:00
[2025-06-08T14:53:55.017+0000] {standard_task_runner.py:87} INFO - Running: ['airflow', 'tasks', 'run', 'transform_customers_csv', 'run_transformation_us', 'manual__2025-06-08T14:52:40.167851+00:00', '--job-id', '434', '--raw', '--subdir', 'DAGS_FOLDER/staging/customer_to_staging.py', '--cfg-path', '/tmp/tmp0l3z5xmn']
[2025-06-08T14:53:55.022+0000] {standard_task_runner.py:88} INFO - Job 434: Subtask run_transformation_us
[2025-06-08T14:53:55.007+0000] {standard_task_runner.py:60} INFO - Started process 27846 to run task
[2025-06-08T14:53:55.253+0000] {logging_mixin.py:188} WARNING - /home/airflow/.local/lib/python3.10/site-packages/airflow/settings.py:194 DeprecationWarning: The sql_alchemy_conn option in [core] has been moved to the sql_alchemy_conn option in [database] - the old setting has been used, but please update your config.
[2025-06-08T14:53:55.465+0000] {task_command.py:423} INFO - Running <TaskInstance: transform_customers_csv.run_transformation_us manual__2025-06-08T14:52:40.167851+00:00 [running]> on host f7e9b9614623
[2025-06-08T14:53:56.015+0000] {taskinstance.py:2480} INFO - Exporting env vars: AIRFLOW_CTX_DAG_OWNER='airflow' AIRFLOW_CTX_DAG_ID='transform_customers_csv' AIRFLOW_CTX_TASK_ID='run_transformation_us' AIRFLOW_CTX_EXECUTION_DATE='2025-06-08T14:52:40.167851+00:00' AIRFLOW_CTX_TRY_NUMBER='1' AIRFLOW_CTX_DAG_RUN_ID='manual__2025-06-08T14:52:40.167851+00:00'
[2025-06-08T14:53:56.024+0000] {logging_mixin.py:188} INFO - Starting transformation for table: customers in region: us
[2025-06-08T14:54:07.736+0000] {logging_mixin.py:188} INFO - Reading data from: /opt/airflow/data/raw/region=us/table=customers/load_date=2025-06-06/
[2025-06-08T14:54:15.700+0000] {local_task_job_runner.py:302} WARNING - State of this instance has been externally set to failed. Terminating instance.
[2025-06-08T14:54:15.708+0000] {process_utils.py:131} INFO - Sending 15 to group 27846. PIDs of all processes in the group: [27867, 27846]
[2025-06-08T14:54:15.710+0000] {process_utils.py:86} INFO - Sending the signal 15 to group 27846
[2025-06-08T14:54:15.711+0000] {taskinstance.py:2450} ERROR - Received SIGTERM. Terminating subprocesses.
[2025-06-08T14:54:15.715+0000] {clientserver.py:538} INFO - Error while receiving.
Traceback (most recent call last):
  File "/home/airflow/.local/lib/python3.10/site-packages/py4j/clientserver.py", line 511, in send_command
    answer = smart_decode(self.stream.readline()[:-1])
  File "/usr/local/lib/python3.10/socket.py", line 705, in readinto
    return self._sock.recv_into(b)
  File "/home/airflow/.local/lib/python3.10/site-packages/airflow/models/taskinstance.py", line 2452, in signal_handler
    raise AirflowException("Task received SIGTERM signal")
airflow.exceptions.AirflowException: Task received SIGTERM signal
[2025-06-08T14:54:15.721+0000] {clientserver.py:543} INFO - Closing down clientserver connection
[2025-06-08T14:54:15.723+0000] {java_gateway.py:1055} ERROR - Exception while sending command.
Traceback (most recent call last):
  File "/home/airflow/.local/lib/python3.10/site-packages/py4j/clientserver.py", line 511, in send_command
    answer = smart_decode(self.stream.readline()[:-1])
  File "/usr/local/lib/python3.10/socket.py", line 705, in readinto
    return self._sock.recv_into(b)
  File "/home/airflow/.local/lib/python3.10/site-packages/airflow/models/taskinstance.py", line 2452, in signal_handler
    raise AirflowException("Task received SIGTERM signal")
airflow.exceptions.AirflowException: Task received SIGTERM signal

During handling of the above exception, another exception occurred:

Traceback (most recent call last):
  File "/home/airflow/.local/lib/python3.10/site-packages/py4j/java_gateway.py", line 1038, in send_command
    response = connection.send_command(command)
  File "/home/airflow/.local/lib/python3.10/site-packages/py4j/clientserver.py", line 539, in send_command
    raise Py4JNetworkError(
py4j.protocol.Py4JNetworkError: Error while sending or receiving
[2025-06-08T14:54:15.726+0000] {clientserver.py:543} INFO - Closing down clientserver connection
[2025-06-08T14:54:15.730+0000] {logging_mixin.py:188} INFO - Error transforming data for us: An error occurred while calling o29.parquet
[2025-06-08T14:54:16.628+0000] {clientserver.py:538} INFO - Error while receiving.
Traceback (most recent call last):
  File "/opt/airflow/scripts/pyspark_jobs/customer.py", line 68, in transform_customers_table
    raise e
  File "/opt/airflow/scripts/pyspark_jobs/customer.py", line 40, in transform_customers_table
    df_raw = spark.read.parquet(input_path)
  File "/home/airflow/.local/lib/python3.10/site-packages/pyspark/sql/readwriter.py", line 544, in parquet
    return self._df(self._jreader.parquet(_to_seq(self._spark._sc, paths)))
  File "/home/airflow/.local/lib/python3.10/site-packages/py4j/java_gateway.py", line 1322, in __call__
    return_value = get_return_value(
  File "/home/airflow/.local/lib/python3.10/site-packages/pyspark/errors/exceptions/captured.py", line 179, in deco
    return f(*a, **kw)
  File "/home/airflow/.local/lib/python3.10/site-packages/py4j/protocol.py", line 334, in get_return_value
    raise Py4JError(
py4j.protocol.Py4JError: An error occurred while calling o29.parquet

During handling of the above exception, another exception occurred:

Traceback (most recent call last):
  File "/home/airflow/.local/lib/python3.10/site-packages/py4j/clientserver.py", line 516, in send_command
    raise Py4JNetworkError("Answer from Java side is empty")
py4j.protocol.Py4JNetworkError: Answer from Java side is empty
[2025-06-08T14:54:16.635+0000] {clientserver.py:543} INFO - Closing down clientserver connection
[2025-06-08T14:54:16.636+0000] {java_gateway.py:1055} ERROR - Exception while sending command.
Traceback (most recent call last):
  File "/opt/airflow/scripts/pyspark_jobs/customer.py", line 68, in transform_customers_table
    raise e
  File "/opt/airflow/scripts/pyspark_jobs/customer.py", line 40, in transform_customers_table
    df_raw = spark.read.parquet(input_path)
  File "/home/airflow/.local/lib/python3.10/site-packages/pyspark/sql/readwriter.py", line 544, in parquet
    return self._df(self._jreader.parquet(_to_seq(self._spark._sc, paths)))
  File "/home/airflow/.local/lib/python3.10/site-packages/py4j/java_gateway.py", line 1322, in __call__
    return_value = get_return_value(
  File "/home/airflow/.local/lib/python3.10/site-packages/pyspark/errors/exceptions/captured.py", line 179, in deco
    return f(*a, **kw)
  File "/home/airflow/.local/lib/python3.10/site-packages/py4j/protocol.py", line 334, in get_return_value
    raise Py4JError(
py4j.protocol.Py4JError: An error occurred while calling o29.parquet

During handling of the above exception, another exception occurred:

Traceback (most recent call last):
  File "/home/airflow/.local/lib/python3.10/site-packages/py4j/clientserver.py", line 516, in send_command
    raise Py4JNetworkError("Answer from Java side is empty")
py4j.protocol.Py4JNetworkError: Answer from Java side is empty

During handling of the above exception, another exception occurred:

Traceback (most recent call last):
  File "/home/airflow/.local/lib/python3.10/site-packages/py4j/java_gateway.py", line 1038, in send_command
    response = connection.send_command(command)
  File "/home/airflow/.local/lib/python3.10/site-packages/py4j/clientserver.py", line 539, in send_command
    raise Py4JNetworkError(
py4j.protocol.Py4JNetworkError: Error while sending or receiving
[2025-06-08T14:54:16.647+0000] {clientserver.py:543} INFO - Closing down clientserver connection
[2025-06-08T14:54:16.653+0000] {logging_mixin.py:188} WARNING - /home/airflow/.local/lib/python3.10/site-packages/pyspark/context.py:657 RuntimeWarning: Unable to cleanly shutdown Spark JVM process. It is possible that the process has crashed, been killed or may also be in a zombie state.
[2025-06-08T14:54:16.940+0000] {clientserver.py:543} INFO - Closing down clientserver connection
[2025-06-08T14:54:16.942+0000] {taskinstance.py:2698} ERROR - Task failed with exception
Traceback (most recent call last):
  File "/opt/airflow/scripts/pyspark_jobs/customer.py", line 68, in transform_customers_table
    raise e
  File "/opt/airflow/scripts/pyspark_jobs/customer.py", line 40, in transform_customers_table
    df_raw = spark.read.parquet(input_path)
  File "/home/airflow/.local/lib/python3.10/site-packages/pyspark/sql/readwriter.py", line 544, in parquet
    return self._df(self._jreader.parquet(_to_seq(self._spark._sc, paths)))
  File "/home/airflow/.local/lib/python3.10/site-packages/py4j/java_gateway.py", line 1322, in __call__
    return_value = get_return_value(
  File "/home/airflow/.local/lib/python3.10/site-packages/pyspark/errors/exceptions/captured.py", line 179, in deco
    return f(*a, **kw)
  File "/home/airflow/.local/lib/python3.10/site-packages/py4j/protocol.py", line 334, in get_return_value
    raise Py4JError(
py4j.protocol.Py4JError: An error occurred while calling o29.parquet

During handling of the above exception, another exception occurred:

Traceback (most recent call last):
  File "/home/airflow/.local/lib/python3.10/site-packages/airflow/models/taskinstance.py", line 433, in _execute_task
    result = execute_callable(context=context, **execute_callable_kwargs)
  File "/home/airflow/.local/lib/python3.10/site-packages/airflow/decorators/base.py", line 241, in execute
    return_value = super().execute(context)
  File "/home/airflow/.local/lib/python3.10/site-packages/airflow/operators/python.py", line 199, in execute
    return_value = self.execute_callable()
  File "/home/airflow/.local/lib/python3.10/site-packages/airflow/operators/python.py", line 216, in execute_callable
    return self.python_callable(*self.op_args, **self.op_kwargs)
  File "/opt/airflow/dags/staging/customer_to_staging.py", line 99, in run_transformation_us
    transform_customers_table(
  File "/opt/airflow/scripts/pyspark_jobs/customer.py", line 70, in transform_customers_table
    spark.stop()
  File "/home/airflow/.local/lib/python3.10/site-packages/pyspark/sql/session.py", line 1799, in stop
    self._jvm.SparkSession.clearDefaultSession()
  File "/home/airflow/.local/lib/python3.10/site-packages/py4j/java_gateway.py", line 1712, in __getattr__
    answer = self._gateway_client.send_command(
  File "/home/airflow/.local/lib/python3.10/site-packages/py4j/java_gateway.py", line 1036, in send_command
    connection = self._get_connection()
  File "/home/airflow/.local/lib/python3.10/site-packages/py4j/clientserver.py", line 284, in _get_connection
    connection = self._create_new_connection()
  File "/home/airflow/.local/lib/python3.10/site-packages/py4j/clientserver.py", line 291, in _create_new_connection
    connection.connect_to_java_server()
  File "/home/airflow/.local/lib/python3.10/site-packages/py4j/clientserver.py", line 438, in connect_to_java_server
    self.socket.connect((self.java_address, self.java_port))
ConnectionRefusedError: [Errno 111] Connection refused
[2025-06-08T14:54:16.984+0000] {taskinstance.py:1138} INFO - Marking task as FAILED. dag_id=transform_customers_csv, task_id=run_transformation_us, execution_date=20250608T145240, start_date=20250608T145354, end_date=20250608T145416
[2025-06-08T14:54:17.052+0000] {standard_task_runner.py:107} ERROR - Failed to execute job 434 for task run_transformation_us ([Errno 111] Connection refused; 27846)
[2025-06-08T14:54:17.165+0000] {process_utils.py:79} INFO - Process psutil.Process(pid=27846, status='terminated', exitcode=1, started='14:53:54') (27846) terminated with exit code 1
[2025-06-08T14:54:17.167+0000] {process_utils.py:79} INFO - Process psutil.Process(pid=27867, status='terminated', started='14:53:56') (27867) terminated with exit code None
